[09/Apr/2023 11:49:30] ERROR [main.modules.study:7] division by zero -- profil
[12/Apr/2023 17:12:16] ERROR [main.modules.accActions:122] (1044, "Access denied for user 'dddeutsch'@'%' to database 'dddeutsch'")
[12/Apr/2023 17:12:16] ERROR [main.modules.accActions:83] (1044, "Access denied for user 'dddeutsch'@'%' to database 'dddeutsch'")
[12/Apr/2023 17:12:16] ERROR [django.request:241] Internal Server Error: /accActions/updateRepeatsInWeek/
Traceback (most recent call last):
  File "/home/dddeutsch/.virtualenvs/dddeutsch.pythonanywhere.com/lib/python3.10/site-packages/django/contrib/sessions/backends/base.py", line 187, in _get_session
    return self._session_cache
AttributeError: 'SessionStore' object has no attribute '_session_cache'

During handling of the above exception, another exception occurred:

Traceback (most recent call last):
  File "/home/dddeutsch/.virtualenvs/dddeutsch.pythonanywhere.com/lib/python3.10/site-packages/django/db/backends/base/base.py", line 282, in ensure_connection
    self.connect()
  File "/home/dddeutsch/.virtualenvs/dddeutsch.pythonanywhere.com/lib/python3.10/site-packages/django/utils/asyncio.py", line 26, in inner
    return func(*args, **kwargs)
  File "/home/dddeutsch/.virtualenvs/dddeutsch.pythonanywhere.com/lib/python3.10/site-packages/django/db/backends/base/base.py", line 263, in connect
    self.connection = self.get_new_connection(conn_params)
  File "/home/dddeutsch/.virtualenvs/dddeutsch.pythonanywhere.com/lib/python3.10/site-packages/django/utils/asyncio.py", line 26, in inner
    return func(*args, **kwargs)
  File "/home/dddeutsch/.virtualenvs/dddeutsch.pythonanywhere.com/lib/python3.10/site-packages/django/db/backends/mysql/base.py", line 247, in get_new_connection
    connection = Database.connect(**conn_params)
  File "/home/dddeutsch/.virtualenvs/dddeutsch.pythonanywhere.com/lib/python3.10/site-packages/MySQLdb/__init__.py", line 123, in Connect
    return Connection(*args, **kwargs)
  File "/home/dddeutsch/.virtualenvs/dddeutsch.pythonanywhere.com/lib/python3.10/site-packages/MySQLdb/connections.py", line 185, in __init__
    super().__init__(*args, **kwargs2)
MySQLdb.OperationalError: (1044, "Access denied for user 'dddeutsch'@'%' to database 'dddeutsch'")

The above exception was the direct cause of the following exception:

Traceback (most recent call last):
  File "/home/dddeutsch/.virtualenvs/dddeutsch.pythonanywhere.com/lib/python3.10/site-packages/django/core/handlers/exception.py", line 55, in inner
    response = get_response(request)
  File "/home/dddeutsch/.virtualenvs/dddeutsch.pythonanywhere.com/lib/python3.10/site-packages/django/core/handlers/base.py", line 197, in _get_response
    response = wrapped_callback(request, *callback_args, **callback_kwargs)
  File "/home/dddeutsch/dddeutsch.pythonanywhere.com/./main/modules/accActions.py", line 64, in updateRepeats
    id = req.user.id
  File "/home/dddeutsch/.virtualenvs/dddeutsch.pythonanywhere.com/lib/python3.10/site-packages/django/utils/functional.py", line 266, in inner
    self._setup()
  File "/home/dddeutsch/.virtualenvs/dddeutsch.pythonanywhere.com/lib/python3.10/site-packages/django/utils/functional.py", line 419, in _setup
    self._wrapped = self._setupfunc()
  File "/home/dddeutsch/.virtualenvs/dddeutsch.pythonanywhere.com/lib/python3.10/site-packages/django/contrib/auth/middleware.py", line 25, in <lambda>
    request.user = SimpleLazyObject(lambda: get_user(request))
  File "/home/dddeutsch/.virtualenvs/dddeutsch.pythonanywhere.com/lib/python3.10/site-packages/django/contrib/auth/middleware.py", line 11, in get_user
    request._cached_user = auth.get_user(request)
  File "/home/dddeutsch/.virtualenvs/dddeutsch.pythonanywhere.com/lib/python3.10/site-packages/django/contrib/auth/__init__.py", line 191, in get_user
    user_id = _get_user_session_key(request)
  File "/home/dddeutsch/.virtualenvs/dddeutsch.pythonanywhere.com/lib/python3.10/site-packages/django/contrib/auth/__init__.py", line 60, in _get_user_session_key
    return get_user_model()._meta.pk.to_python(request.session[SESSION_KEY])
  File "/home/dddeutsch/.virtualenvs/dddeutsch.pythonanywhere.com/lib/python3.10/site-packages/django/contrib/sessions/backends/base.py", line 53, in __getitem__
    return self._session[key]
  File "/home/dddeutsch/.virtualenvs/dddeutsch.pythonanywhere.com/lib/python3.10/site-packages/django/contrib/sessions/backends/base.py", line 192, in _get_session
    self._session_cache = self.load()
  File "/home/dddeutsch/.virtualenvs/dddeutsch.pythonanywhere.com/lib/python3.10/site-packages/django/contrib/sessions/backends/db.py", line 42, in load
    s = self._get_session_from_db()
  File "/home/dddeutsch/.virtualenvs/dddeutsch.pythonanywhere.com/lib/python3.10/site-packages/django/contrib/sessions/backends/db.py", line 32, in _get_session_from_db
    return self.model.objects.get(
  File "/home/dddeutsch/.virtualenvs/dddeutsch.pythonanywhere.com/lib/python3.10/site-packages/django/db/models/manager.py", line 85, in manager_method
    return getattr(self.get_queryset(), name)(*args, **kwargs)
  File "/home/dddeutsch/.virtualenvs/dddeutsch.pythonanywhere.com/lib/python3.10/site-packages/django/db/models/query.py", line 646, in get
    num = len(clone)
  File "/home/dddeutsch/.virtualenvs/dddeutsch.pythonanywhere.com/lib/python3.10/site-packages/django/db/models/query.py", line 376, in __len__
    self._fetch_all()
  File "/home/dddeutsch/.virtualenvs/dddeutsch.pythonanywhere.com/lib/python3.10/site-packages/django/db/models/query.py", line 1866, in _fetch_all
    self._result_cache = list(self._iterable_class(self))
  File "/home/dddeutsch/.virtualenvs/dddeutsch.pythonanywhere.com/lib/python3.10/site-packages/django/db/models/query.py", line 87, in __iter__
    results = compiler.execute_sql(
  File "/home/dddeutsch/.virtualenvs/dddeutsch.pythonanywhere.com/lib/python3.10/site-packages/django/db/models/sql/compiler.py", line 1393, in execute_sql
    cursor = self.connection.cursor()
  File "/home/dddeutsch/.virtualenvs/dddeutsch.pythonanywhere.com/lib/python3.10/site-packages/django/utils/asyncio.py", line 26, in inner
    return func(*args, **kwargs)
  File "/home/dddeutsch/.virtualenvs/dddeutsch.pythonanywhere.com/lib/python3.10/site-packages/django/db/backends/base/base.py", line 323, in cursor
    return self._cursor()
  File "/home/dddeutsch/.virtualenvs/dddeutsch.pythonanywhere.com/lib/python3.10/site-packages/django/db/backends/base/base.py", line 299, in _cursor
    self.ensure_connection()
  File "/home/dddeutsch/.virtualenvs/dddeutsch.pythonanywhere.com/lib/python3.10/site-packages/django/utils/asyncio.py", line 26, in inner
    return func(*args, **kwargs)
  File "/home/dddeutsch/.virtualenvs/dddeutsch.pythonanywhere.com/lib/python3.10/site-packages/django/db/backends/base/base.py", line 281, in ensure_connection
    with self.wrap_database_errors:
  File "/home/dddeutsch/.virtualenvs/dddeutsch.pythonanywhere.com/lib/python3.10/site-packages/django/db/utils.py", line 91, in __exit__
    raise dj_exc_value.with_traceback(traceback) from exc_value
  File "/home/dddeutsch/.virtualenvs/dddeutsch.pythonanywhere.com/lib/python3.10/site-packages/django/db/backends/base/base.py", line 282, in ensure_connection
    self.connect()
  File "/home/dddeutsch/.virtualenvs/dddeutsch.pythonanywhere.com/lib/python3.10/site-packages/django/utils/asyncio.py", line 26, in inner
    return func(*args, **kwargs)
  File "/home/dddeutsch/.virtualenvs/dddeutsch.pythonanywhere.com/lib/python3.10/site-packages/django/db/backends/base/base.py", line 263, in connect
    self.connection = self.get_new_connection(conn_params)
  File "/home/dddeutsch/.virtualenvs/dddeutsch.pythonanywhere.com/lib/python3.10/site-packages/django/utils/asyncio.py", line 26, in inner
    return func(*args, **kwargs)
  File "/home/dddeutsch/.virtualenvs/dddeutsch.pythonanywhere.com/lib/python3.10/site-packages/django/db/backends/mysql/base.py", line 247, in get_new_connection
    connection = Database.connect(**conn_params)
  File "/home/dddeutsch/.virtualenvs/dddeutsch.pythonanywhere.com/lib/python3.10/site-packages/MySQLdb/__init__.py", line 123, in Connect
    return Connection(*args, **kwargs)
  File "/home/dddeutsch/.virtualenvs/dddeutsch.pythonanywhere.com/lib/python3.10/site-packages/MySQLdb/connections.py", line 185, in __init__
    super().__init__(*args, **kwargs2)
django.db.utils.OperationalError: (1044, "Access denied for user 'dddeutsch'@'%' to database 'dddeutsch'")
[12/Apr/2023 19:07:34] ERROR [main.modules.accActions:86] User matching query does not exist.
[12/Apr/2023 19:10:54] ERROR [root:170] /home/dddeutsch/.virtualenvs/dddeutsch.pythonanywhere.com/lib/python3.10/site-packages/django/db/models/fields/__init__.py:1564: RuntimeWarning: DateTimeField WordsStat.lastRepeat received a naive datetime (2023-04-12 19:10:53) while time zone support is active.
[12/Apr/2023 19:10:54] ERROR [root:170]   warnings.warn(
[12/Apr/2023 19:10:54] ERROR [root:170] /home/dddeutsch/.virtualenvs/dddeutsch.pythonanywhere.com/lib/python3.10/site-packages/django/db/models/fields/__init__.py:1564: RuntimeWarning: DateTimeField WordsStat.nextRepeat received a naive datetime (2023-04-13 19:10:53) while time zone support is active.
[12/Apr/2023 19:10:54] ERROR [root:170]   warnings.warn(
[12/Apr/2023 19:11:25] ERROR [root:170] /home/dddeutsch/.virtualenvs/dddeutsch.pythonanywhere.com/lib/python3.10/site-packages/django/db/models/fields/__init__.py:1564: RuntimeWarning: DateTimeField WordsStat.lastRepeat received a naive datetime (2023-04-12 19:11:17) while time zone support is active.
[12/Apr/2023 19:11:25] ERROR [root:170]   warnings.warn(
[12/Apr/2023 19:11:25] ERROR [root:170] /home/dddeutsch/.virtualenvs/dddeutsch.pythonanywhere.com/lib/python3.10/site-packages/django/db/models/fields/__init__.py:1564: RuntimeWarning: DateTimeField WordsStat.nextRepeat received a naive datetime (2023-04-13 19:11:17) while time zone support is active.
[12/Apr/2023 19:11:25] ERROR [root:170]   warnings.warn(
[12/Apr/2023 19:11:25] ERROR [root:170] /home/dddeutsch/.virtualenvs/dddeutsch.pythonanywhere.com/lib/python3.10/site-packages/django/db/models/fields/__init__.py:1564: RuntimeWarning: DateTimeField WordsStat.lastRepeat received a naive datetime (2023-04-12 19:11:18) while time zone support is active.
[12/Apr/2023 19:11:25] ERROR [root:170]   warnings.warn(
[12/Apr/2023 19:11:25] ERROR [root:170] /home/dddeutsch/.virtualenvs/dddeutsch.pythonanywhere.com/lib/python3.10/site-packages/django/db/models/fields/__init__.py:1564: RuntimeWarning: DateTimeField WordsStat.nextRepeat received a naive datetime (2023-04-13 19:11:18) while time zone support is active.
[12/Apr/2023 19:11:25] ERROR [root:170]   warnings.warn(
[12/Apr/2023 19:11:25] ERROR [root:170] /home/dddeutsch/.virtualenvs/dddeutsch.pythonanywhere.com/lib/python3.10/site-packages/django/db/models/fields/__init__.py:1564: RuntimeWarning: DateTimeField WordsStat.lastRepeat received a naive datetime (2023-04-12 19:11:19) while time zone support is active.
[12/Apr/2023 19:11:25] ERROR [root:170]   warnings.warn(
[12/Apr/2023 19:11:25] ERROR [root:170] /home/dddeutsch/.virtualenvs/dddeutsch.pythonanywhere.com/lib/python3.10/site-packages/django/db/models/fields/__init__.py:1564: RuntimeWarning: DateTimeField WordsStat.nextRepeat received a naive datetime (2023-04-14 19:11:19) while time zone support is active.
[12/Apr/2023 19:11:25] ERROR [root:170]   warnings.warn(
[12/Apr/2023 19:11:25] ERROR [root:170] /home/dddeutsch/.virtualenvs/dddeutsch.pythonanywhere.com/lib/python3.10/site-packages/django/db/models/fields/__init__.py:1564: RuntimeWarning: DateTimeField WordsStat.nextRepeat received a naive datetime (2023-04-16 19:11:19) while time zone support is active.
[12/Apr/2023 19:11:25] ERROR [root:170]   warnings.warn(
[12/Apr/2023 19:11:25] ERROR [root:170] /home/dddeutsch/.virtualenvs/dddeutsch.pythonanywhere.com/lib/python3.10/site-packages/django/db/models/fields/__init__.py:1564: RuntimeWarning: DateTimeField WordsStat.nextRepeat received a naive datetime (2023-04-13 19:11:19) while time zone support is active.
[12/Apr/2023 19:11:25] ERROR [root:170]   warnings.warn(
[12/Apr/2023 19:11:25] ERROR [root:170] /home/dddeutsch/.virtualenvs/dddeutsch.pythonanywhere.com/lib/python3.10/site-packages/django/db/models/fields/__init__.py:1564: RuntimeWarning: DateTimeField WordsStat.lastRepeat received a naive datetime (2023-04-12 19:11:20) while time zone support is active.
[12/Apr/2023 19:11:25] ERROR [root:170]   warnings.warn(
[12/Apr/2023 19:11:25] ERROR [root:170] /home/dddeutsch/.virtualenvs/dddeutsch.pythonanywhere.com/lib/python3.10/site-packages/django/db/models/fields/__init__.py:1564: RuntimeWarning: DateTimeField WordsStat.nextRepeat received a naive datetime (2023-04-13 19:11:20) while time zone support is active.
[12/Apr/2023 19:11:25] ERROR [root:170]   warnings.warn(
[12/Apr/2023 19:11:25] ERROR [root:170] /home/dddeutsch/.virtualenvs/dddeutsch.pythonanywhere.com/lib/python3.10/site-packages/django/db/models/fields/__init__.py:1564: RuntimeWarning: DateTimeField WordsStat.lastRepeat received a naive datetime (2023-04-12 19:11:21) while time zone support is active.
[12/Apr/2023 19:11:25] ERROR [root:170]   warnings.warn(
[12/Apr/2023 19:11:25] ERROR [root:170] /home/dddeutsch/.virtualenvs/dddeutsch.pythonanywhere.com/lib/python3.10/site-packages/django/db/models/fields/__init__.py:1564: RuntimeWarning: DateTimeField WordsStat.nextRepeat received a naive datetime (2023-04-13 19:11:21) while time zone support is active.
[12/Apr/2023 19:11:25] ERROR [root:170]   warnings.warn(
[12/Apr/2023 19:11:25] ERROR [root:170] /home/dddeutsch/.virtualenvs/dddeutsch.pythonanywhere.com/lib/python3.10/site-packages/django/db/models/fields/__init__.py:1564: RuntimeWarning: DateTimeField WordsStat.lastRepeat received a naive datetime (2023-04-12 19:11:22) while time zone support is active.
[12/Apr/2023 19:11:25] ERROR [root:170]   warnings.warn(
[12/Apr/2023 19:11:25] ERROR [root:170] /home/dddeutsch/.virtualenvs/dddeutsch.pythonanywhere.com/lib/python3.10/site-packages/django/db/models/fields/__init__.py:1564: RuntimeWarning: DateTimeField WordsStat.nextRepeat received a naive datetime (2023-04-13 19:11:22) while time zone support is active.
[12/Apr/2023 19:11:25] ERROR [root:170]   warnings.warn(
[12/Apr/2023 19:11:25] ERROR [root:170] /home/dddeutsch/.virtualenvs/dddeutsch.pythonanywhere.com/lib/python3.10/site-packages/django/db/models/fields/__init__.py:1564: RuntimeWarning: DateTimeField WordsStat.nextRepeat received a naive datetime (2023-04-14 19:11:22) while time zone support is active.
[12/Apr/2023 19:11:25] ERROR [root:170]   warnings.warn(
[12/Apr/2023 19:11:25] ERROR [root:170] /home/dddeutsch/.virtualenvs/dddeutsch.pythonanywhere.com/lib/python3.10/site-packages/django/db/models/fields/__init__.py:1564: RuntimeWarning: DateTimeField WordsStat.lastRepeat received a naive datetime (2023-04-12 19:11:23) while time zone support is active.
[12/Apr/2023 19:11:25] ERROR [root:170]   warnings.warn(
[12/Apr/2023 19:11:25] ERROR [root:170] /home/dddeutsch/.virtualenvs/dddeutsch.pythonanywhere.com/lib/python3.10/site-packages/django/db/models/fields/__init__.py:1564: RuntimeWarning: DateTimeField WordsStat.nextRepeat received a naive datetime (2023-04-13 19:11:23) while time zone support is active.
[12/Apr/2023 19:11:25] ERROR [root:170]   warnings.warn(
[12/Apr/2023 19:11:25] ERROR [root:170] /home/dddeutsch/.virtualenvs/dddeutsch.pythonanywhere.com/lib/python3.10/site-packages/django/db/models/fields/__init__.py:1564: RuntimeWarning: DateTimeField WordsStat.lastRepeat received a naive datetime (2023-04-12 19:11:24) while time zone support is active.
[12/Apr/2023 19:11:25] ERROR [root:170]   warnings.warn(
[12/Apr/2023 19:11:25] ERROR [root:170] /home/dddeutsch/.virtualenvs/dddeutsch.pythonanywhere.com/lib/python3.10/site-packages/django/db/models/fields/__init__.py:1564: RuntimeWarning: DateTimeField WordsStat.nextRepeat received a naive datetime (2023-04-13 19:11:24) while time zone support is active.
[12/Apr/2023 19:11:25] ERROR [root:170]   warnings.warn(
